Workbook
Name Slicer_Product_Line: #N/A
Name Slicer_Test_Type: #N/A

Sheet Exploratory Analysis
B3: Row Labels | C3: Count of Product_Line | E3: Row Labels | F3: Count of Site | H3: Row Labels | I3: Count of Test_Type
B4: Aroma Chemical | C4: 433 | E4: ashford | F4: 232 | H4: Density_g_ml | I4: 285
B5: Essential Oil Blend | C5: 413 | E5: Ashford UK | F5: 127 | H5: Microbial_Count_CFU_g | I5: 295
B6: Flavor Compound | C6: 392 | E6: BUD | F6: 105 | H6: Moisture_Pct | I6: 279
B7: Food Ingredient Extract | C7: 361 | E7: Budapest | F7: 222 | H7: Particle_Size_um | I7: 311
B8: Fragrance Oil | C8: 416 | E8: Budapest Site | F8: 107 | H8: pH | I8: 264
B9: (blank) | E9: dortmund | F9: 253 | H9: Purity_Pct | I9: 286
B10: Grand Total | C10: 2015 | E10: Dortmund DE | F10: 130 | H10: Residual_Solvent_ppm | I10: 295
E11: E. Hanover | F11: 149 | H11: (blank)
E12: East Hanover | F12: 300 | H12: Grand Total | I12: 2015
B13: Row Labels | C13: Count of Analyst | E13: VERNIER | F13: 299
B14: A. Kovacs | C14: 197 | E14: Vernier CH | F14: 91
B15: J NAGY | C15: 188 | E15: (blank)
B16: J. Nagy | C16: 214 | E16: Grand Total | F16: 2015
B17: K. Varga | C17: 194
B18: L. Rossi | C18: 213
B19: M. Toth | C19: 375
B20: P. Meier | C20: 208
B21: S. Fischer | C21: 235
B22: T. Weber | C22: 191
B23: (blank)
B24: Grand Total | C24: 2015

Sheet mapping Site table
B3: original value | C3: standardized value
B4: ASHFORD UK | C4: Ashford UK
B5: VERNIER | C5: Vernier CH
B6: EAST HANOVER | C6: East Hanover
B7: ASHFORD | C7: Ashford UK
B8: VERNIER CH | C8: Vernier CH
B9: DORTMUND | C9: Dortmund DE
B10: E. HANOVER | C10: East Hanover
B11: BUDAPEST | C11: Budapest
B12: DORTMUND DE | C12: Dortmund DE
B13: BUDAPEST SITE | C13: Budapest
B14: BUD | C14: Budapest

Sheet Raw_LIMS_Export
A1: Sample_ID | B1: Batch_ID | C1: Product_Line | D1: Site | E1: Site_Helper | F1: Test_Type | G1: Result_Value | H1: Unit | I1: Spec_Lower | J1: Spec_Upper | K1: Helper_Date | L1: Test_Date | M1: Analyst
A2: S001578 | B2: ARO-2024-00352 | C2: Aroma Chemical | D2: Ashford UK | E2: =UPPER(D2) -> ASHFORD UK | F2: Residual_Solvent_ppm | G2: 18.09 | H2: ppm | I2: 0 | J2: 120 | K2: =IF(L2="","", IF(MID(L2,5,1)="-", DATE(LEFT(L2,4),MID(L2,6,2),RIGHT(L2,2)), DATE(RIGHT(L2,4),MID(L2,4,2),LEFT(L2,2)) )) -> 45350 | L2: 28/02/2024 | M2: A. Kovacs
A3: S000141 | B3: FOO-2024-00034 | C3: Food Ingredient Extract | D3: VERNIER | E3: =UPPER(D3) -> VERNIER | F3: Density_g_ml | G3: 0.92 | H3: g/ml | I3: 0.88 | J3: 0.97 | K3: =IF(L3="","", IF(MID(L3,5,1)="-", DATE(LEFT(L3,4),MID(L3,6,2),RIGHT(L3,2)), DATE(RIGHT(L3,4),MID(L3,4,2),LEFT(L3,2)) )) -> 45399 | L3: 2024-04-17 | M3: J NAGY
A4: S000111 | B4: ARO-2025-00025 | C4: Aroma Chemical | D4: East Hanover | E4: =UPPER(D4) -> EAST HANOVER | F4: Particle_Size_um | G4: 224.54 | H4: um | I4: 150 | J4: 400 | K4: =IF(L4="","", IF(MID(L4,5,1)="-", DATE(LEFT(L4,4),MID(L4,6,2),RIGHT(L4,2)), DATE(RIGHT(L4,4),MID(L4,4,2),LEFT(L4,2)) )) -> 45924 | L4: 24/09/2025 | M4: J NAGY
A5: S000260 | B5: ESS-2025-00059 | C5: Essential Oil Blend | D5: vernier | E5: =UPPER(D5) -> VERNIER | F5: Purity_Pct | G5: 97.98 | H5: % | I5: 97 | J5: 100 | K5: =IF(L5="","", IF(MID(L5,5,1)="-", DATE(LEFT(L5,4),MID(L5,6,2),RIGHT(L5,2)), DATE(RIGHT(L5,4),MID(L5,4,2),LEFT(L5,2)) )) -> 45982 | L5: 2025-11-21 | M5: A. Kovacs
A6: S001392 | B6: ARO-2024-00311 | C6: Aroma Chemical | D6: EAST HANOVER | E6: =UPPER(D6) -> EAST HANOVER | F6: Purity_Pct | G6: 95.2 | H6: % | I6: 97 | J6: 100 | K6: =IF(L6="","", IF(MID(L6,5,1)="-", DATE(LEFT(L6,4),MID(L6,6,2),RIGHT(L6,2)), DATE(RIGHT(L6,4),MID(L6,4,2),LEFT(L6,2)) )) -> 45488 | L6: 2024-07-15 | M6: S. Fischer
A7: S001745 | B7: FOO-2024-00389 | C7: Food Ingredient Extract | D7: ashford | E7: =UPPER(D7) -> ASHFORD | F7: Particle_Size_um | G7: 227.62 | H7: um | I7: 150 | J7: 400 | K7: =IF(L7="","", IF(MID(L7,5,1)="-", DATE(LEFT(L7,4),MID(L7,6,2),RIGHT(L7,2)), DATE(RIGHT(L7,4),MID(L7,4,2),LEFT(L7,2)) )) -> 45446 | L7: 2024-06-03 | M7: M. Toth
A8: S000515 | B8: FOO-2025-00116 | C8: Food Ingredient Extract | D8: Vernier CH | E8: =UPPER(D8) -> VERNIER CH | F8: Moisture_Pct | G8: 0.38 | H8: % | I8: 0 | J8: 1 | K8: =IF(L8="","", IF(MID(L8,5,1)="-", DATE(LEFT(L8,4),MID(L8,6,2),RIGHT(L8,2)), DATE(RIGHT(L8,4),MID(L8,4,2),LEFT(L8,2)) )) -> 46008 | L8: 2025-12-17 | M8: J NAGY
A9: S001518 | B9: FRA-2024-00338 | C9: Fragrance Oil | D9: dortmund | E9: =UPPER(D9) -> DORTMUND | F9: Particle_Size_um | G9: 318.47 | H9: um | I9: 150 | J9: 400 | K9: =IF(L9="","", IF(MID(L9,5,1)="-", DATE(LEFT(L9,4),MID(L9,6,2),RIGHT(L9,2)), DATE(RIGHT(L9,4),MID(L9,4,2),LEFT(L9,2)) )) -> 45501 | L9: 2024-07-28 | M9: A. Kovacs
A10: S001387 | B10: FLA-2025-00310 | C10: Flavor Compound | D10: E. Hanover | E10: =UPPER(D10) -> E. HANOVER | F10: Purity_Pct | G10: 98.21 | H10: % | I10: 97 | J10: 100 | K10: =IF(L10="","", IF(MID(L10,5,1)="-", DATE(LEFT(L10,4),MID(L10,6,2),RIGHT(L10,2)), DATE(RIGHT(L10,4),MID(L10,4,2),LEFT(L10,2)) )) -> 45881 | L10: 2025-08-12 | M10: J NAGY
A11: S001059 | B11: FOO-2024-00237 | C11: Food Ingredient Extract | D11: Budapest | E11: =UPPER(D11) -> BUDAPEST | F11: Residual_Solvent_ppm | G11: 33.35 | H11: ppm | I11: 0 | J11: 120 | K11: =IF(L11="","", IF(MID(L11,5,1)="-", DATE(LEFT(L11,4),MID(L11,6,2),RIGHT(L11,2)), DATE(RIGHT(L11,4),MID(L11,4,2),LEFT(L11,2)) )) -> 45655 | L11: 2024-12-29 | M11: K. Varga
A12: S001922 | B12: ARO-2024-00430 | C12: Aroma Chemical | D12: East Hanover | E12: =UPPER(D12) -> EAST HANOVER | F12: Purity_Pct | G12: 97.78 | H12: % | I12: 97 | J12: 100 | K12: =IF(L12="","", IF(MID(L12,5,1)="-", DATE(LEFT(L12,4),MID(L12,6,2),RIGHT(L12,2)), DATE(RIGHT(L12,4),MID(L12,4,2),LEFT(L12,2)) )) -> 45577 | L12: 2024-10-12 | M12: m. toth
A13: S001737 | B13: ARO-2024-00388 | C13: Aroma Chemical | D13: VERNIER | E13: =UPPER(D13) -> VERNIER | F13: Moisture_Pct | G13: 0.37 | H13: % | I13: 0 | J13: 1 | K13: =IF(L13="","", IF(MID(L13,5,1)="-", DATE(LEFT(L13,4),MID(L13,6,2),RIGHT(L13,2)), DATE(RIGHT(L13,4),MID(L13,4,2),LEFT(L13,2)) )) -> 45530 | L13: 2024-08-26 | M13: S. Fischer
... A15: S001274 | B15: ARO-2024-00285 | C15: Aroma Chemical | D15: vernier | E15: =UPPER(D15) -> VERNIER | F15: Residual_Solvent_ppm | G15: 48.04 | H15: ppm | I15: 0 | J15: 120 | K15: =IF(L15="","", IF(MID(L15,5,1)="-", DATE(LEFT(L15,4),MID(L15,6,2),RIGHT(L15,2)), DATE(RIGHT(L15,4),MID(L15,4,2),LEFT(L15,2)) )) -> 45529 | L15: 2024-08-25 | M15: P. Meier
A16: S001927 | B16: FOO-2024-00431 | C16: Food Ingredient Extract | D16: East Hanover | E16: =UPPER(D16) -> EAST HANOVER | F16: pH | G16: 6.7 | I16: 6 | J16: 7.5 | K16: =IF(L16="","", IF(MID(L16,5,1)="-", DATE(LEFT(L16,4),MID(L16,6,2),RIGHT(L16,2)), DATE(RIGHT(L16,4),MID(L16,4,2),LEFT(L16,2)) )) -> 45351 | L16: 2024-02-29 | M16: T. Weber
A17: S001545 | B17: FLA-2024-00344 | C17: Flavor Compound | D17: Vernier | E17: =UPPER(D17) -> VERNIER | F17: Purity_Pct | G17: 101.8 | H17: % | I17: 97 | J17: 100 | K17: =IF(L17="","", IF(MID(L17,5,1)="-", DATE(LEFT(L17,4),MID(L17,6,2),RIGHT(L17,2)), DATE(RIGHT(L17,4),MID(L17,4,2),LEFT(L17,2)) )) -> 45294 | L17: 2024-01-03 | M17: J. Nagy
A18: S001090 | B18: FOO-2025-00245 | C18: Food Ingredient Extract | D18: E. Hanover | E18: =UPPER(D18) -> E. HANOVER | F18: Particle_Size_um | G18: 184.37 | H18: um | I18: 150 | J18: 400 | K18: =IF(L18="","", IF(MID(L18,5,1)="-", DATE(LEFT(L18,4),MID(L18,6,2),RIGHT(L18,2)), DATE(RIGHT(L18,4),MID(L18,4,2),LEFT(L18,2)) )) -> 45827 | L18: 19/06/2025 | M18: A. Kovacs
A19: S001355 | B19: ESS-2024-00303 | C19: Essential Oil Blend | D19: dortmund | E19: =UPPER(D19) -> DORTMUND | F19: Density_g_ml | G19: 0.9 | H19: g/ml | I19: 0.88 | J19: 0.97 | K19: =IF(L19="","", IF(MID(L19,5,1)="-", DATE(LEFT(L19,4),MID(L19,6,2),RIGHT(L19,2)), DATE(RIGHT(L19,4),MID(L19,4,2),LEFT(L19,2)) )) -> 45654 | L19: 2024-12-28 | M19: K. Varga
A20: S000359 | B20: ESS-2025-00081 | C20: Essential Oil Blend | D20: Dortmund | E20: =UPPER(D20) -> DORTMUND | F20: Particle_Size_um | G20: 239.92 | H20: um | I20: 150 | J20: 400 | K20: =IF(L20="","", IF(MID(L20,5,1)="-", DATE(LEFT(L20,4),MID(L20,6,2),RIGHT(L20,2)), DATE(RIGHT(L20,4),MID(L20,4,2),LEFT(L20,2)) )) -> 45740 | L20: 2025-03-24 | M20: P. Meier
A21: S001328 | B21: ARO-2024-00296 | C21: Aroma Chemical | D21: Vernier CH | E21: =UPPER(D21) -> VERNIER CH | F21: Moisture_Pct | G21: 0.34 | H21: % | I21: 0 | J21: 1 | K21: =IF(L21="","", IF(MID(L21,5,1)="-", DATE(LEFT(L21,4),MID(L21,6,2),RIGHT(L21,2)), DATE(RIGHT(L21,4),MID(L21,4,2),LEFT(L21,2)) )) -> 45613 | L21: 2024-11-17 | M21: A. Kovacs
A22: S000197 | B22: ESS-2025-00045 | C22: Essential Oil Blend | D22: Dortmund DE | E22: =UPPER(D22) -> DORTMUND DE | F22: Residual_Solvent_ppm | G22: 41.98 | H22: ppm | I22: 0 | J22: 120 | K22: =IF(L22="","", IF(MID(L22,5,1)="-", DATE(LEFT(L22,4),MID(L22,6,2),RIGHT(L22,2)), DATE(RIGHT(L22,4),MID(L22,4,2),LEFT(L22,2)) )) -> 45887 | L22: 2025-08-18 | M22: T. Weber
A23: S001683 | B23: FRA-2024-00376 | C23: Fragrance Oil | D23: Ashford UK | E23: =UPPER(D23) -> ASHFORD UK | F23: Microbial_Count_CFU_g | G23: 4.69 | H23: CFU/g | I23: 0 | J23: 100 | K23: =IF(L23="","", IF(MID(L23,5,1)="-", DATE(LEFT(L23,4),MID(L23,6,2),RIGHT(L23,2)), DATE(RIGHT(L23,4),MID(L23,4,2),LEFT(L23,2)) )) -> 45409 | L23: 2024-04-27 | M23: J. Nagy
A24: S001692 | B24: ESS-2024-00379 | C24: Essential Oil Blend | D24: EAST HANOVER | E24: =UPPER(D24) -> EAST HANOVER | F24: Microbial_Count_CFU_g | G24: -25 | H24: CFU/g | I24: 0 | J24: 100 | K24: =IF(L24="","", IF(MID(L24,5,1)="-", DATE(LEFT(L24,4),MID(L24,6,2),RIGHT(L24,2)), DATE(RIGHT(L24,4),MID(L24,4,2),LEFT(L24,2)) )) -> 45330 | L24: 2024-02-08 | M24: S. Fischer
A25: S000611 | B25: FLA-2024-00138 | C25: Flavor Compound | D25: Ashford UK | E25: =UPPER(D25) -> ASHFORD UK | F25: Moisture_Pct | G25: 0.31 | H25: % | I25: 0 | J25: 1 | K25: =IF(L25="","", IF(MID(L25,5,1)="-", DATE(LEFT(L25,4),MID(L25,6,2),RIGHT(L25,2)), DATE(RIGHT(L25,4),MID(L25,4,2),LEFT(L25,2)) )) -> 45615 | L25: 19/11/2024 | M25: M. Toth
A26: S000362 | B26: FLA-2025-00082 | C26: Flavor Compound | D26: Ashford | E26: =UPPER(D26) -> ASHFORD | F26: Purity_Pct | H26: % | I26: 97 | J26: 100 | K26: =IF(L26="","", IF(MID(L26,5,1)="-", DATE(LEFT(L26,4),MID(L26,6,2),RIGHT(L26,2)), DATE(RIGHT(L26,4),MID(L26,4,2),LEFT(L26,2)) )) -> 45853 | L26: 2025-07-15 | M26: M. Toth
A27: S000003 | B27: ESS-2025-00001 | C27: Essential Oil Blend | D27: vernier | E27: =UPPER(D27) -> VERNIER | F27: Particle_Size_um | G27: 215.63 | H27: um | I27: 150 | J27: 400 | K27: =IF(L27="","", IF(MID(L27,5,1)="-", DATE(LEFT(L27,4),MID(L27,6,2),RIGHT(L27,2)), DATE(RIGHT(L27,4),MID(L27,4,2),LEFT(L27,2)) )) -> 45769 | L27: 2025-04-22 | M27: M. Toth
A28: S000667 | B28: FLA-2024-00152 | C28: Flavor Compound | D28: Budapest | E28: =UPPER(D28) -> BUDAPEST | F28: Particle_Size_um | G28: 253.19 | H28: um | I28: 150 | J28: 400 | K28: =IF(L28="","", IF(MID(L28,5,1)="-", DATE(LEFT(L28,4),MID(L28,6,2),RIGHT(L28,2)), DATE(RIGHT(L28,4),MID(L28,4,2),LEFT(L28,2)) )) -> 45643 | L28: 2024-12-17 | M28: S. Fischer
A29: S000528 | B29: ARO-2024-00119 | C29: Aroma Chemical | D29: E. Hanover | E29: =UPPER(D29) -> E. HANOVER | F29: Residual_Solvent_ppm | G29: 45.4 | H29: ppm | I29: 0 | J29: 120 | K29: =IF(L29="","", IF(MID(L29,5,1)="-", DATE(LEFT(L29,4),MID(L29,6,2),RIGHT(L29,2)), DATE(RIGHT(L29,4),MID(L29,4,2),LEFT(L29,2)) )) -> 45374 | L29: 2024-03-23 | M29: A. Kovacs
A30: S001118 | B30: FOO-2025-00251 | C30: Food Ingredient Extract | D30: Budapest | E30: =UPPER(D30) -> BUDAPEST | F30: Purity_Pct | G30: 97.88 | H30: % | I30: 97 | J30: 100 | K30: =IF(L30="","", IF(MID(L30,5,1)="-", DATE(LEFT(L30,4),MID(L30,6,2),RIGHT(L30,2)), DATE(RIGHT(L30,4),MID(L30,4,2),LEFT(L30,2)) )) -> 45969 | L30: 2025-11-08 | M30: J NAGY
A31: S000703 | B31: FRA-2024-00160 | C31: Fragrance Oil | D31: Dortmund DE | E31: =UPPER(D31) -> DORTMUND DE | F31: Moisture_Pct | G31: 0.4 | H31: % | I31: 0 | J31: 1 | K31: =IF(L31="","", IF(MID(L31,5,1)="-", DATE(LEFT(L31,4),MID(L31,6,2),RIGHT(L31,2)), DATE(RIGHT(L31,4),MID(L31,4,2),LEFT(L31,2)) )) -> 45386 | L31: 2024-04-04 | M31: K. Varga
A32: S000603 | B32: FRA-2025-00136 | C32: Fragrance Oil | D32: ashford | E32: =UPPER(D32) -> ASHFORD | F32: Residual_Solvent_ppm | G32: 50.68 | H32: ppm | I32: 0 | J32: 120 | K32: =IF(L32="","", IF(MID(L32,5,1)="-", DATE(LEFT(L32,4),MID(L32,6,2),RIGHT(L32,2)), DATE(RIGHT(L32,4),MID(L32,4,2),LEFT(L32,2)) )) -> 45824 | L32: 2025-06-16 | M32: A. Kovacs
A33: S000659 | B33: FRA-2025-00150 | C33: Fragrance Oil | D33: VERNIER | E33: =UPPER(D33) -> VERNIER | F33: Particle_Size_um | G33: 244.91 | H33: um | I33: 150 | J33: 400 | K33: =IF(L33="","", IF(MID(L33,5,1)="-", DATE(LEFT(L33,4),MID(L33,6,2),RIGHT(L33,2)), DATE(RIGHT(L33,4),MID(L33,4,2),LEFT(L33,2)) )) -> 45774 | L33: 2025-04-27 | M33: P. Meier
A34: S001918 | B34: FLA-2024-00429 | C34: Flavor Compound | D34: vernier | E34: =UPPER(D34) -> VERNIER | F34: pH | G34: 6.76 | I34: 6 | J34: 7.5 | K34: =IF(L34="","", IF(MID(L34,5,1)="-", DATE(LEFT(L34,4),MID(L34,6,2),RIGHT(L34,2)), DATE(RIGHT(L34,4),MID(L34,4,2),LEFT(L34,2)) )) -> 45431 | L34: 2024-05-19 | M34: J. Nagy
A35: S001825 | B35: ESS-2024-00408 | C35: Essential Oil Blend | D35: Budapest | E35: =UPPER(D35) -> BUDAPEST | F35: Density_g_ml | G35: 0.89 | H35: g/ml | I35: 0.88 | J35: 0.97 | K35: =IF(L35="","", IF(MID(L35,5,1)="-", DATE(LEFT(L35,4),MID(L35,6,2),RIGHT(L35,2)), DATE(RIGHT(L35,4),MID(L35,4,2),LEFT(L35,2)) )) -> 45350 | L35: 2024-02-28 | M35: A. Kovacs
A36: S000763 | B36: ARO-2024-00172 | C36: Aroma Chemical | D36: Budapest | E36: =UPPER(D36) -> BUDAPEST | F36: Purity_Pct | G36: 98.67 | H36: % | I36: 97 | J36: 100 | K36: =IF(L36="","", IF(MID(L36,5,1)="-", DATE(LEFT(L36,4),MID(L36,6,2),RIGHT(L36,2)), DATE(RIGHT(L36,4),MID(L36,4,2),LEFT(L36,2)) )) -> 45655 | L36: 2024-12-29 | M36: S. Fischer
A37: S000375 | B37: ARO-2025-00085 | C37: Aroma Chemical | D37: Dortmund | E37: =UPPER(D37) -> DORTMUND | F37: Density_g_ml | G37: 0.79 | H37: g/ml | I37: 0.88 | J37: 0.97 | K37: =IF(L37="","", IF(MID(L37,5,1)="-", DATE(LEFT(L37,4),MID(L37,6,2),RIGHT(L37,2)), DATE(RIGHT(L37,4),MID(L37,4,2),LEFT(L37,2)) )) -> 45739 | L37: 2025-03-23 | M37: m. toth
A38: S001960 | B38: FRA-2024-00438 | C38: Fragrance Oil | D38: Budapest Site | E38: =UPPER(D38) -> BUDAPEST SITE | F38: Moisture_Pct | G38: 0.21 | H38: % | I38: 0 | J38: 1 | K38: =IF(L38="","", IF(MID(L38,5,1)="-", DATE(LEFT(L38,4),MID(L38,6,2),RIGHT(L38,2)), DATE(RIGHT(L38,4),MID(L38,4,2),LEFT(L38,2)) )) -> 45543 | L38: 2024-09-08 | M38: P. Meier
A39: S000673 | B39: FOO-2025-00153 | C39: Food Ingredient Extract | D39: Dortmund DE | E39: =UPPER(D39) -> DORTMUND DE | F39: Purity_Pct | G39: 98.78 | H39: % | I39: 97 | J39: 100 | K39: =IF(L39="","", IF(MID(L39,5,1)="-", DATE(LEFT(L39,4),MID(L39,6,2),RIGHT(L39,2)), DATE(RIGHT(L39,4),MID(L39,4,2),LEFT(L39,2)) )) -> 45845 | L39: 07/07/2025 | M39: A. Kovacs
A40: S001038 | B40: FOO-2024-00233 | C40: Food Ingredient Extract | D40: dortmund | E40: =UPPER(D40) -> DORTMUND | F40: Microbial_Count_CFU_g | G40: -27.76 | H40: CFU/g | I40: 0 | J40: 100 | K40: =IF(L40="","", IF(MID(L40,5,1)="-", DATE(LEFT(L40,4),MID(L40,6,2),RIGHT(L40,2)), DATE(RIGHT(L40,4),MID(L40,4,2),LEFT(L40,2)) )) -> 45452 | L40: 2024-06-09 | M40: K. Varga
A41: S000946 | B41: FLA-2024-00214 | C41: Flavor Compound | D41: E. Hanover | E41: =UPPER(D41) -> E. HANOVER | F41: Microbial_Count_CFU_g | G41: 30.04 | H41: CFU/g | I41: 0 | J41: 100 | K41: =IF(L41="","", IF(MID(L41,5,1)="-", DATE(LEFT(L41,4),MID(L41,6,2),RIGHT(L41,2)), DATE(RIGHT(L41,4),MID(L41,4,2),LEFT(L41,2)) )) -> 45398 | L41: 2024-04-16 | M41: M. Toth
...

Sheet Batch outcome by site
A3: Distinct Count of Batch_ID | B3: Column Labels
A4: Row Labels | B4: Fail | C4: Pass | D4: Pending | E4: Grand Total
A5: Ashford UK | B5: 0.31707317 | C5: 0.59756098 | D5: 0.085365854 | E5: 1
A6: Budapest | B6: 0.21875 | C6: 0.6875 | D6: 0.09375 | E6: 1
A7: Dortmund DE | B7: 0.36046512 | C7: 0.58139535 | D7: 0.058139535 | E7: 1
A8: East Hanover | B8: 0.34693878 | C8: 0.6122449 | D8: 0.040816327 | E8: 1
A9: Vernier CH | B9: 0.35714286 | C9: 0.53571429 | D9: 0.10714286 | E9: 1
A10: Grand Total | B10: 0.31838565 | C10: 0.60538117 | D10: 0.076233184 | E10: 1

Sheet Test_outcome
A3: Count of Sample_ID | B3: Column Labels
B4: Fail | C4: Missing | D4: Pass | E4: Grand Total | F4: Pass Rate
A5: Density_g_ml | B5: 31 | C5: 6 | D5: 248 | E5: 285 | F5: =D5/E5 -> 0.87017544
A6: Microbial_Count_CFU_g | B6: 95 | C6: 3 | D6: 197 | E6: 295 | F6: =D6/E6 -> 0.66779661
A7: Moisture_Pct | B7: 7 | C7: 4 | D7: 268 | E7: 279 | F7: =D7/E7 -> 0.96057348
A8: Particle_Size_um | B8: 11 | C8: 6 | D8: 294 | E8: 311 | F8: =D8/E8 -> 0.94533762
A9: pH | B9: 23 | C9: 5 | D9: 236 | E9: 264 | F9: =D9/E9 -> 0.89393939
A10: Purity_Pct | B10: 14 | C10: 7 | D10: 265 | E10: 286 | F10: =D10/E10 -> 0.92657343
A11: Residual_Solvent_ppm | B11: 12 | C11: 11 | D11: 272 | E11: 295 | F11: =D11/E11 -> 0.9220339
A12: Grand Total | B12: 193 | C12: 42 | D12: 1780 | E12: 2015 | F12: =D12/E12 -> 0.88337469

Sheet LIMS_Export_worked
A1: Sample_ID | B1: Batch_ID | C1: Product_Line | D1: Site | E1: Test_Type | F1: Result_Exists | G1: Result_Pass | H1: Batch_Result | I1: Result_Value | J1: Unit | K1: Spec_Lower | L1: Spec_Upper | M1: Test_Date | N1: Analyst
A2: S001578 | B2: ARO-2024-00352 | C2: Aroma Chemical | D2: =_xlfn.XLOOKUP(Raw_LIMS_Export!E2,'mapping Site table'!$B$4:$B$14,'mapping Site table'!$C$4:$C$14,Raw_LIMS_Export!E2) -> Ashford UK | E2: Residual_Solvent_ppm | F2: =IF(I2="",0,1) -> 1 | G2: =IF(I2="", "Missing", IF(AND(I2>=K2, I2<=L2), "Pass", "Fail")) -> Pass | H2: =IF(COUNTIFS($B$2:$B$2016,B2,$G$2:$G$2016,"Fail")>0,"Fail", IF(COUNTIFS($B$2:$B$2016,B2,$G$2:$G$2016,"Missing")>0,"Pending", "Pass")) -> Pending | I2: 18.09 | J2: ppm | K2: 0 | L2: 120 | M2: =Raw_LIMS_Export!K2 -> 45350 | N2: A. Kovacs
A3: S000141 | B3: FOO-2024-00034 | C3: Food Ingredient Extract | D3: =_xlfn.XLOOKUP(Raw_LIMS_Export!E3,'mapping Site table'!$B$4:$B$14,'mapping Site table'!$C$4:$C$14,Raw_LIMS_Export!E3) -> Vernier CH | E3: Density_g_ml | F3: =IF(I3="",0,1) -> 1 | G3: =IF(I3="", "Missing", IF(AND(I3>=K3, I3<=L3), "Pass", "Fail")) -> Pass | H3: =IF(COUNTIFS($B$2:$B$2016,B3,$G$2:$G$2016,"Fail")>0,"Fail", IF(COUNTIFS($B$2:$B$2016,B3,$G$2:$G$2016,"Missing")>0,"Pending", "Pass")) -> Pass | I3: 0.92 | J3: g/ml | K3: 0.88 | L3: 0.97 | M3: =Raw_LIMS_Export!K3 -> 45399 | N3: J NAGY
A4: S000111 | B4: ARO-2025-00025 | C4: Aroma Chemical | D4: =_xlfn.XLOOKUP(Raw_LIMS_Export!E4,'mapping Site table'!$B$4:$B$14,'mapping Site table'!$C$4:$C$14,Raw_LIMS_Export!E4) -> East Hanover | E4: Particle_Size_um | F4: =IF(I4="",0,1) -> 1 | G4: =IF(I4="", "Missing", IF(AND(I4>=K4, I4<=L4), "Pass", "Fail")) -> Pass | H4: =IF(COUNTIFS($B$2:$B$2016,B4,$G$2:$G$2016,"Fail")>0,"Fail", IF(COUNTIFS($B$2:$B$2016,B4,$G$2:$G$2016,"Missing")>0,"Pending", "Pass")) -> Pass | I4: 224.54 | J4: um | K4: 150 | L4: 400 | M4: =Raw_LIMS_Export!K4 -> 45924 | N4: J NAGY
A5: S000260 | B5: ESS-2025-00059 | C5: Essential Oil Blend | D5: =_xlfn.XLOOKUP(Raw_LIMS_Export!E5,'mapping Site table'!$B$4:$B$14,'mapping Site table'!$C$4:$C$14,Raw_LIMS_Export!E5) -> Vernier CH | E5: Purity_Pct | F5: =IF(I5="",0,1) -> 1 | G5: =IF(I5="", "Missing", IF(AND(I5>=K5, I5<=L5), "Pass", "Fail")) -> Pass | H5: =IF(COUNTIFS($B$2:$B$2016,B5,$G$2:$G$2016,"Fail")>0,"Fail", IF(COUNTIFS($B$2:$B$2016,B5,$G$2:$G$2016,"Missing")>0,"Pending", "Pass")) -> Pass | I5: 97.98 | J5: % | K5: 97 | L5: 100 | M5: =Raw_LIMS_Export!K5 -> 45982 | N5: A. Kovacs
A6: S001392 | B6: ARO-2024-00311 | C6: Aroma Chemical | D6: =_xlfn.XLOOKUP(Raw_LIMS_Export!E6,'mapping Site table'!$B$4:$B$14,'mapping Site table'!$C$4:$C$14,Raw_LIMS_Export!E6) -> East Hanover | E6: Purity_Pct | F6: =IF(I6="",0,1) -> 1 | G6: =IF(I6="", "Missing", IF(AND(I6>=K6, I6<=L6), "Pass", "Fail")) -> Fail | H6: =IF(COUNTIFS($B$2:$B$2016,B6,$G$2:$G$2016,"Fail")>0,"Fail", IF(COUNTIFS($B$2:$B$2016,B6,$G$2:$G$2016,"Missing")>0,"Pending", "Pass")) -> Fail | I6: 95.2 | J6: % | K6: 97 | L6: 100 | M6: =Raw_LIMS_Export!K6 -> 45488 | N6: S. Fischer
A7: S001745 | B7: FOO-2024-00389 | C7: Food Ingredient Extract | D7: =_xlfn.XLOOKUP(Raw_LIMS_Export!E7,'mapping Site table'!$B$4:$B$14,'mapping Site table'!$C$4:$C$14,Raw_LIMS_Export!E7) -> Ashford UK | E7: Particle_Size_um | F7: =IF(I7="",0,1) -> 1 | G7: =IF(I7="", "Missing", IF(AND(I7>=K7, I7<=L7), "Pass", "Fail")) -> Pass | H7: =IF(COUNTIFS($B$2:$B$2016,B7,$G$2:$G$2016,"Fail")>0,"Fail", IF(COUNTIFS($B$2:$B$2016,B7,$G$2:$G$2016,"Missing")>0,"Pending", "Pass")) -> Pass | I7: 227.62 | J7: um | K7: 150 | L7: 400 | M7: =Raw_LIMS_Export!K7 -> 45446 | N7: M. Toth
A8: S000515 | B8: FOO-2025-00116 | C8: Food Ingredient Extract | D8: =_xlfn.XLOOKUP(Raw_LIMS_Export!E8,'mapping Site table'!$B$4:$B$14,'mapping Site table'!$C$4:$C$14,Raw_LIMS_Export!E8) -> Vernier CH | E8: Moisture_Pct | F8: =IF(I8="",0,1) -> 1 | G8: =IF(I8="", "Missing", IF(AND(I8>=K8, I8<=L8), "Pass", "Fail")) -> Pass | H8: =IF(COUNTIFS($B$2:$B$2016,B8,$G$2:$G$2016,"Fail")>0,"Fail", IF(COUNTIFS($B$2:$B$2016,B8,$G$2:$G$2016,"Missing")>0,"Pending", "Pass")) -> Fail | I8: 0.38 | J8: % | K8: 0 | L8: 1 | M8: =Raw_LIMS_Export!K8 -> 46008 | N8: J NAGY
A9: S001518 | B9: FRA-2024-00338 | C9: Fragrance Oil | D9: =_xlfn.XLOOKUP(Raw_LIMS_Export!E9,'mapping Site table'!$B$4:$B$14,'mapping Site table'!$C$4:$C$14,Raw_LIMS_Export!E9) -> Dortmund DE | E9: Particle_Size_um | F9: =IF(I9="",0,1) -> 1 | G9: =IF(I9="", "Missing", IF(AND(I9>=K9, I9<=L9), "Pass", "Fail")) -> Pass | H9: =IF(COUNTIFS($B$2:$B$2016,B9,$G$2:$G$2016,"Fail")>0,"Fail", IF(COUNTIFS($B$2:$B$2016,B9,$G$2:$G$2016,"Missing")>0,"Pending", "Pass")) -> Fail | I9: 318.47 | J9: um | K9: 150 | L9: 400 | M9: =Raw_LIMS_Export!K9 -> 45501 | N9: A. Kovacs
A10: S001387 | B10: FLA-2025-00310 | C10: Flavor Compound | D10: =_xlfn.XLOOKUP(Raw_LIMS_Export!E10,'mapping Site table'!$B$4:$B$14,'mapping Site table'!$C$4:$C$14,Raw_LIMS_Export!E10) -> East Hanover | E10: Purity_Pct | F10: =IF(I10="",0,1) -> 1 | G10: =IF(I10="", "Missing", IF(AND(I10>=K10, I10<=L10), "Pass", "Fail")) -> Pass | H10: =IF(COUNTIFS($B$2:$B$2016,B10,$G$2:$G$2016,"Fail")>0,"Fail", IF(COUNTIFS($B$2:$B$2016,B10,$G$2:$G$2016,"Missing")>0,"Pending", "Pass")) -> Pass | I10: 98.21 | J10: % | K10: 97 | L10: 100 | M10: =Raw_LIMS_Export!K10 -> 45881 | N10: J NAGY
A11: S001059 | B11: FOO-2024-00237 | C11: Food Ingredient Extract | D11: =_xlfn.XLOOKUP(Raw_LIMS_Export!E11,'mapping Site table'!$B$4:$B$14,'mapping Site table'!$C$4:$C$14,Raw_LIMS_Export!E11) -> Budapest | E11: Residual_Solvent_ppm | F11: =IF(I11="",0,1) -> 1 | G11: =IF(I11="", "Missing", IF(AND(I11>=K11, I11<=L11), "Pass", "Fail")) -> Pass | H11: =IF(COUNTIFS($B$2:$B$2016,B11,$G$2:$G$2016,"Fail")>0,"Fail", IF(COUNTIFS($B$2:$B$2016,B11,$G$2:$G$2016,"Missing")>0,"Pending", "Pass")) -> Pass | I11: 33.35 | J11: ppm | K11: 0 | L11: 120 | M11: =Raw_LIMS_Export!K11 -> 45655 | N11: K. Varga
A12: S001922 | B12: ARO-2024-00430 | C12: Aroma Chemical | D12: =_xlfn.XLOOKUP(Raw_LIMS_Export!E12,'mapping Site table'!$B$4:$B$14,'mapping Site table'!$C$4:$C$14,Raw_LIMS_Export!E12) -> East Hanover | E12: Purity_Pct | F12: =IF(I12="",0,1) -> 1 | G12: =IF(I12="", "Missing", IF(AND(I12>=K12, I12<=L12), "Pass", "Fail")) -> Pass | H12: =IF(COUNTIFS($B$2:$B$2016,B12,$G$2:$G$2016,"Fail")>0,"Fail", IF(COUNTIFS($B$2:$B$2016,B12,$G$2:$G$2016,"Missing")>0,"Pending", "Pass")) -> Fail | I12: 97.78 | J12: % | K12: 97 | L12: 100 | M12: =Raw_LIMS_Export!K12 -> 45577 | N12: m. toth
A13: S001737 | B13: ARO-2024-00388 | C13: Aroma Chemical | D13: =_xlfn.XLOOKUP(Raw_LIMS_Export!E13,'mapping Site table'!$B$4:$B$14,'mapping Site table'!$C$4:$C$14,Raw_LIMS_Export!E13) -> Vernier CH | E13: Moisture_Pct | F13: =IF(I13="",0,1) -> 1 | G13: =IF(I13="", "Missing", IF(AND(I13>=K13, I13<=L13), "Pass", "Fail")) -> Pass | H13: =IF(COUNTIFS($B$2:$B$2016,B13,$G$2:$G$2016,"Fail")>0,"Fail", IF(COUNTIFS($B$2:$B$2016,B13,$G$2:$G$2016,"Missing")>0,"Pending", "Pass")) -> Pending | I13: 0.37 | J13: % | K13: 0 | L13: 1 | M13: =Raw_LIMS_Export!K13 -> 45530 | N13: S. Fischer
... A15: S001274 | B15: ARO-2024-00285 | C15: Aroma Chemical | D15: =_xlfn.XLOOKUP(Raw_LIMS_Export!E15,'mapping Site table'!$B$4:$B$14,'mapping Site table'!$C$4:$C$14,Raw_LIMS_Export!E15) -> Vernier CH | E15: Residual_Solvent_ppm | F15: =IF(I15="",0,1) -> 1 | G15: =IF(I15="", "Missing", IF(AND(I15>=K15, I15<=L15), "Pass", "Fail")) -> Pass | H15: =IF(COUNTIFS($B$2:$B$2016,B15,$G$2:$G$2016,"Fail")>0,"Fail", IF(COUNTIFS($B$2:$B$2016,B15,$G$2:$G$2016,"Missing")>0,"Pending", "Pass")) -> Fail | I15: 48.04 | J15: ppm | K15: 0 | L15: 120 | M15: =Raw_LIMS_Export!K15 -> 45529 | N15: P. Meier
A16: S001927 | B16: FOO-2024-00431 | C16: Food Ingredient Extract | D16: =_xlfn.XLOOKUP(Raw_LIMS_Export!E16,'mapping Site table'!$B$4:$B$14,'mapping Site table'!$C$4:$C$14,Raw_LIMS_Export!E16) -> East Hanover | E16: pH | F16: =IF(I16="",0,1) -> 1 | G16: =IF(I16="", "Missing", IF(AND(I16>=K16, I16<=L16), "Pass", "Fail")) -> Pass | H16: =IF(COUNTIFS($B$2:$B$2016,B16,$G$2:$G$2016,"Fail")>0,"Fail", IF(COUNTIFS($B$2:$B$2016,B16,$G$2:$G$2016,"Missing")>0,"Pending", "Pass")) -> Fail | I16: 6.7 | K16: 6 | L16: 7.5 | M16: =Raw_LIMS_Export!K16 -> 45351 | N16: T. Weber
A17: S001545 | B17: FLA-2024-00344 | C17: Flavor Compound | D17: =_xlfn.XLOOKUP(Raw_LIMS_Export!E17,'mapping Site table'!$B$4:$B$14,'mapping Site table'!$C$4:$C$14,Raw_LIMS_Export!E17) -> Vernier CH | E17: Purity_Pct | F17: =IF(I17="",0,1) -> 1 | G17: =IF(I17="", "Missing", IF(AND(I17>=K17, I17<=L17), "Pass", "Fail")) -> Fail | H17: =IF(COUNTIFS($B$2:$B$2016,B17,$G$2:$G$2016,"Fail")>0,"Fail", IF(COUNTIFS($B$2:$B$2016,B17,$G$2:$G$2016,"Missing")>0,"Pending", "Pass")) -> Fail | I17: 101.8 | J17: % | K17: 97 | L17: 100 | M17: =Raw_LIMS_Export!K17 -> 45294 | N17: J. Nagy
A18: S001090 | B18: FOO-2025-00245 | C18: Food Ingredient Extract | D18: =_xlfn.XLOOKUP(Raw_LIMS_Export!E18,'mapping Site table'!$B$4:$B$14,'mapping Site table'!$C$4:$C$14,Raw_LIMS_Export!E18) -> East Hanover | E18: Particle_Size_um | F18: =IF(I18="",0,1) -> 1 | G18: =IF(I18="", "Missing", IF(AND(I18>=K18, I18<=L18), "Pass", "Fail")) -> Pass | H18: =IF(COUNTIFS($B$2:$B$2016,B18,$G$2:$G$2016,"Fail")>0,"Fail", IF(COUNTIFS($B$2:$B$2016,B18,$G$2:$G$2016,"Missing")>0,"Pending", "Pass")) -> Pass | I18: 184.37 | J18: um | K18: 150 | L18: 400 | M18: =Raw_LIMS_Export!K18 -> 45827 | N18: A. Kovacs
A19: S001355 | B19: ESS-2024-00303 | C19: Essential Oil Blend | D19: =_xlfn.XLOOKUP(Raw_LIMS_Export!E19,'mapping Site table'!$B$4:$B$14,'mapping Site table'!$C$4:$C$14,Raw_LIMS_Export!E19) -> Dortmund DE | E19: Density_g_ml | F19: =IF(I19="",0,1) -> 1 | G19: =IF(I19="", "Missing", IF(AND(I19>=K19, I19<=L19), "Pass", "Fail")) -> Pass | H19: =IF(COUNTIFS($B$2:$B$2016,B19,$G$2:$G$2016,"Fail")>0,"Fail", IF(COUNTIFS($B$2:$B$2016,B19,$G$2:$G$2016,"Missing")>0,"Pending", "Pass")) -> Pass | I19: 0.9 | J19: g/ml | K19: 0.88 | L19: 0.97 | M19: =Raw_LIMS_Export!K19 -> 45654 | N19: K. Varga
A20: S000359 | B20: ESS-2025-00081 | C20: Essential Oil Blend | D20: =_xlfn.XLOOKUP(Raw_LIMS_Export!E20,'mapping Site table'!$B$4:$B$14,'mapping Site table'!$C$4:$C$14,Raw_LIMS_Export!E20) -> Dortmund DE | E20: Particle_Size_um | F20: =IF(I20="",0,1) -> 1 | G20: =IF(I20="", "Missing", IF(AND(I20>=K20, I20<=L20), "Pass", "Fail")) -> Pass | H20: =IF(COUNTIFS($B$2:$B$2016,B20,$G$2:$G$2016,"Fail")>0,"Fail", IF(COUNTIFS($B$2:$B$2016,B20,$G$2:$G$2016,"Missing")>0,"Pending", "Pass")) -> Pass | I20: 239.92 | J20: um | K20: 150 | L20: 400 | M20: =Raw_LIMS_Export!K20 -> 45740 | N20: P. Meier
A21: S001328 | B21: ARO-2024-00296 | C21: Aroma Chemical | D21: =_xlfn.XLOOKUP(Raw_LIMS_Export!E21,'mapping Site table'!$B$4:$B$14,'mapping Site table'!$C$4:$C$14,Raw_LIMS_Export!E21) -> Vernier CH | E21: Moisture_Pct | F21: =IF(I21="",0,1) -> 1 | G21: =IF(I21="", "Missing", IF(AND(I21>=K21, I21<=L21), "Pass", "Fail")) -> Pass | H21: =IF(COUNTIFS($B$2:$B$2016,B21,$G$2:$G$2016,"Fail")>0,"Fail", IF(COUNTIFS($B$2:$B$2016,B21,$G$2:$G$2016,"Missing")>0,"Pending", "Pass")) -> Pass | I21: 0.34 | J21: % | K21: 0 | L21: 1 | M21: =Raw_LIMS_Export!K21 -> 45613 | N21: A. Kovacs
A22: S000197 | B22: ESS-2025-00045 | C22: Essential Oil Blend | D22: =_xlfn.XLOOKUP(Raw_LIMS_Export!E22,'mapping Site table'!$B$4:$B$14,'mapping Site table'!$C$4:$C$14,Raw_LIMS_Export!E22) -> Dortmund DE | E22: Residual_Solvent_ppm | F22: =IF(I22="",0,1) -> 1 | G22: =IF(I22="", "Missing", IF(AND(I22>=K22, I22<=L22), "Pass", "Fail")) -> Pass | H22: =IF(COUNTIFS($B$2:$B$2016,B22,$G$2:$G$2016,"Fail")>0,"Fail", IF(COUNTIFS($B$2:$B$2016,B22,$G$2:$G$2016,"Missing")>0,"Pending", "Pass")) -> Fail | I22: 41.98 | J22: ppm | K22: 0 | L22: 120 | M22: =Raw_LIMS_Export!K22 -> 45887 | N22: T. Weber
A23: S001683 | B23: FRA-2024-00376 | C23: Fragrance Oil | D23: =_xlfn.XLOOKUP(Raw_LIMS_Export!E23,'mapping Site table'!$B$4:$B$14,'mapping Site table'!$C$4:$C$14,Raw_LIMS_Export!E23) -> Ashford UK | E23: Microbial_Count_CFU_g | F23: =IF(I23="",0,1) -> 1 | G23: =IF(I23="", "Missing", IF(AND(I23>=K23, I23<=L23), "Pass", "Fail")) -> Pass | H23: =IF(COUNTIFS($B$2:$B$2016,B23,$G$2:$G$2016,"Fail")>0,"Fail", IF(COUNTIFS($B$2:$B$2016,B23,$G$2:$G$2016,"Missing")>0,"Pending", "Pass")) -> Fail | I23: 4.69 | J23: CFU/g | K23: 0 | L23: 100 | M23: =Raw_LIMS_Export!K23 -> 45409 | N23: J. Nagy
A24: S001692 | B24: ESS-2024-00379 | C24: Essential Oil Blend | D24: =_xlfn.XLOOKUP(Raw_LIMS_Export!E24,'mapping Site table'!$B$4:$B$14,'mapping Site table'!$C$4:$C$14,Raw_LIMS_Export!E24) -> East Hanover | E24: Microbial_Count_CFU_g | F24: =IF(I24="",0,1) -> 1 | G24: =IF(I24="", "Missing", IF(AND(I24>=K24, I24<=L24), "Pass", "Fail")) -> Fail | H24: =IF(COUNTIFS($B$2:$B$2016,B24,$G$2:$G$2016,"Fail")>0,"Fail", IF(COUNTIFS($B$2:$B$2016,B24,$G$2:$G$2016,"Missing")>0,"Pending", "Pass")) -> Fail | I24: -25 | J24: CFU/g | K24: 0 | L24: 100 | M24: =Raw_LIMS_Export!K24 -> 45330 | N24: S. Fischer
A25: S000611 | B25: FLA-2024-00138 | C25: Flavor Compound | D25: =_xlfn.XLOOKUP(Raw_LIMS_Export!E25,'mapping Site table'!$B$4:$B$14,'mapping Site table'!$C$4:$C$14,Raw_LIMS_Export!E25) -> Ashford UK | E25: Moisture_Pct | F25: =IF(I25="",0,1) -> 1 | G25: =IF(I25="", "Missing", IF(AND(I25>=K25, I25<=L25), "Pass", "Fail")) -> Pass | H25: =IF(COUNTIFS($B$2:$B$2016,B25,$G$2:$G$2016,"Fail")>0,"Fail", IF(COUNTIFS($B$2:$B$2016,B25,$G$2:$G$2016,"Missing")>0,"Pending", "Pass")) -> Fail | I25: 0.31 | J25: % | K25: 0 | L25: 1 | M25: =Raw_LIMS_Export!K25 -> 45615 | N25: M. Toth
A26: S000362 | B26: FLA-2025-00082 | C26: Flavor Compound | D26: =_xlfn.XLOOKUP(Raw_LIMS_Export!E26,'mapping Site table'!$B$4:$B$14,'mapping Site table'!$C$4:$C$14,Raw_LIMS_Export!E26) -> Ashford UK | E26: Purity_Pct | F26: =IF(I26="",0,1) -> 0 | G26: =IF(I26="", "Missing", IF(AND(I26>=K26, I26<=L26), "Pass", "Fail")) -> Missing | H26: =IF(COUNTIFS($B$2:$B$2016,B26,$G$2:$G$2016,"Fail")>0,"Fail", IF(COUNTIFS($B$2:$B$2016,B26,$G$2:$G$2016,"Missing")>0,"Pending", "Pass")) -> Pending | J26: % | K26: 97 | L26: 100 | M26: =Raw_LIMS_Export!K26 -> 45853 | N26: M. Toth
A27: S000003 | B27: ESS-2025-00001 | C27: Essential Oil Blend | D27: =_xlfn.XLOOKUP(Raw_LIMS_Export!E27,'mapping Site table'!$B$4:$B$14,'mapping Site table'!$C$4:$C$14,Raw_LIMS_Export!E27) -> Vernier CH | E27: Particle_Size_um | F27: =IF(I27="",0,1) -> 1 | G27: =IF(I27="", "Missing", IF(AND(I27>=K27, I27<=L27), "Pass", "Fail")) -> Pass | H27: =IF(COUNTIFS($B$2:$B$2016,B27,$G$2:$G$2016,"Fail")>0,"Fail", IF(COUNTIFS($B$2:$B$2016,B27,$G$2:$G$2016,"Missing")>0,"Pending", "Pass")) -> Pass | I27: 215.63 | J27: um | K27: 150 | L27: 400 | M27: =Raw_LIMS_Export!K27 -> 45769 | N27: M. Toth
A28: S000667 | B28: FLA-2024-00152 | C28: Flavor Compound | D28: =_xlfn.XLOOKUP(Raw_LIMS_Export!E28,'mapping Site table'!$B$4:$B$14,'mapping Site table'!$C$4:$C$14,Raw_LIMS_Export!E28) -> Budapest | E28: Particle_Size_um | F28: =IF(I28="",0,1) -> 1 | G28: =IF(I28="", "Missing", IF(AND(I28>=K28, I28<=L28), "Pass", "Fail")) -> Pass | H28: =IF(COUNTIFS($B$2:$B$2016,B28,$G$2:$G$2016,"Fail")>0,"Fail", IF(COUNTIFS($B$2:$B$2016,B28,$G$2:$G$2016,"Missing")>0,"Pending", "Pass")) -> Pass | I28: 253.19 | J28: um | K28: 150 | L28: 400 | M28: =Raw_LIMS_Export!K28 -> 45643 | N28: S. Fischer
A29: S000528 | B29: ARO-2024-00119 | C29: Aroma Chemical | D29: =_xlfn.XLOOKUP(Raw_LIMS_Export!E29,'mapping Site table'!$B$4:$B$14,'mapping Site table'!$C$4:$C$14,Raw_LIMS_Export!E29) -> East Hanover | E29: Residual_Solvent_ppm | F29: =IF(I29="",0,1) -> 1 | G29: =IF(I29="", "Missing", IF(AND(I29>=K29, I29<=L29), "Pass", "Fail")) -> Pass | H29: =IF(COUNTIFS($B$2:$B$2016,B29,$G$2:$G$2016,"Fail")>0,"Fail", IF(COUNTIFS($B$2:$B$2016,B29,$G$2:$G$2016,"Missing")>0,"Pending", "Pass")) -> Pass | I29: 45.4 | J29: ppm | K29: 0 | L29: 120 | M29: =Raw_LIMS_Export!K29 -> 45374 | N29: A. Kovacs
A30: S001118 | B30: FOO-2025-00251 | C30: Food Ingredient Extract | D30: =_xlfn.XLOOKUP(Raw_LIMS_Export!E30,'mapping Site table'!$B$4:$B$14,'mapping Site table'!$C$4:$C$14,Raw_LIMS_Export!E30) -> Budapest | E30: Purity_Pct | F30: =IF(I30="",0,1) -> 1 | G30: =IF(I30="", "Missing", IF(AND(I30>=K30, I30<=L30), "Pass", "Fail")) -> Pass | H30: =IF(COUNTIFS($B$2:$B$2016,B30,$G$2:$G$2016,"Fail")>0,"Fail", IF(COUNTIFS($B$2:$B$2016,B30,$G$2:$G$2016,"Missing")>0,"Pending", "Pass")) -> Fail | I30: 97.88 | J30: % | K30: 97 | L30: 100 | M30: =Raw_LIMS_Export!K30 -> 45969 | N30: J NAGY
A31: S000703 | B31: FRA-2024-00160 | C31: Fragrance Oil | D31: =_xlfn.XLOOKUP(Raw_LIMS_Export!E31,'mapping Site table'!$B$4:$B$14,'mapping Site table'!$C$4:$C$14,Raw_LIMS_Export!E31) -> Dortmund DE | E31: Moisture_Pct | F31: =IF(I31="",0,1) -> 1 | G31: =IF(I31="", "Missing", IF(AND(I31>=K31, I31<=L31), "Pass", "Fail")) -> Pass | H31: =IF(COUNTIFS($B$2:$B$2016,B31,$G$2:$G$2016,"Fail")>0,"Fail", IF(COUNTIFS($B$2:$B$2016,B31,$G$2:$G$2016,"Missing")>0,"Pending", "Pass")) -> Fail | I31: 0.4 | J31: % | K31: 0 | L31: 1 | M31: =Raw_LIMS_Export!K31 -> 45386 | N31: K. Varga
A32: S000603 | B32: FRA-2025-00136 | C32: Fragrance Oil | D32: =_xlfn.XLOOKUP(Raw_LIMS_Export!E32,'mapping Site table'!$B$4:$B$14,'mapping Site table'!$C$4:$C$14,Raw_LIMS_Export!E32) -> Ashford UK | E32: Residual_Solvent_ppm | F32: =IF(I32="",0,1) -> 1 | G32: =IF(I32="", "Missing", IF(AND(I32>=K32, I32<=L32), "Pass", "Fail")) -> Pass | H32: =IF(COUNTIFS($B$2:$B$2016,B32,$G$2:$G$2016,"Fail")>0,"Fail", IF(COUNTIFS($B$2:$B$2016,B32,$G$2:$G$2016,"Missing")>0,"Pending", "Pass")) -> Pass | I32: 50.68 | J32: ppm | K32: 0 | L32: 120 | M32: =Raw_LIMS_Export!K32 -> 45824 | N32: A. Kovacs
A33: S000659 | B33: FRA-2025-00150 | C33: Fragrance Oil | D33: =_xlfn.XLOOKUP(Raw_LIMS_Export!E33,'mapping Site table'!$B$4:$B$14,'mapping Site table'!$C$4:$C$14,Raw_LIMS_Export!E33) -> Vernier CH | E33: Particle_Size_um | F33: =IF(I33="",0,1) -> 1 | G33: =IF(I33="", "Missing", IF(AND(I33>=K33, I33<=L33), "Pass", "Fail")) -> Pass | H33: =IF(COUNTIFS($B$2:$B$2016,B33,$G$2:$G$2016,"Fail")>0,"Fail", IF(COUNTIFS($B$2:$B$2016,B33,$G$2:$G$2016,"Missing")>0,"Pending", "Pass")) -> Fail | I33: 244.91 | J33: um | K33: 150 | L33: 400 | M33: =Raw_LIMS_Export!K33 -> 45774 | N33: P. Meier
A34: S001918 | B34: FLA-2024-00429 | C34: Flavor Compound | D34: =_xlfn.XLOOKUP(Raw_LIMS_Export!E34,'mapping Site table'!$B$4:$B$14,'mapping Site table'!$C$4:$C$14,Raw_LIMS_Export!E34) -> Vernier CH | E34: pH | F34: =IF(I34="",0,1) -> 1 | G34: =IF(I34="", "Missing", IF(AND(I34>=K34, I34<=L34), "Pass", "Fail")) -> Pass | H34: =IF(COUNTIFS($B$2:$B$2016,B34,$G$2:$G$2016,"Fail")>0,"Fail", IF(COUNTIFS($B$2:$B$2016,B34,$G$2:$G$2016,"Missing")>0,"Pending", "Pass")) -> Pass | I34: 6.76 | K34: 6 | L34: 7.5 | M34: =Raw_LIMS_Export!K34 -> 45431 | N34: J. Nagy
A35: S001825 | B35: ESS-2024-00408 | C35: Essential Oil Blend | D35: =_xlfn.XLOOKUP(Raw_LIMS_Export!E35,'mapping Site table'!$B$4:$B$14,'mapping Site table'!$C$4:$C$14,Raw_LIMS_Export!E35) -> Budapest | E35: Density_g_ml | F35: =IF(I35="",0,1) -> 1 | G35: =IF(I35="", "Missing", IF(AND(I35>=K35, I35<=L35), "Pass", "Fail")) -> Pass | H35: =IF(COUNTIFS($B$2:$B$2016,B35,$G$2:$G$2016,"Fail")>0,"Fail", IF(COUNTIFS($B$2:$B$2016,B35,$G$2:$G$2016,"Missing")>0,"Pending", "Pass")) -> Pending | I35: 0.89 | J35: g/ml | K35: 0.88 | L35: 0.97 | M35: =Raw_LIMS_Export!K35 -> 45350 | N35: A. Kovacs
A36: S000763 | B36: ARO-2024-00172 | C36: Aroma Chemical | D36: =_xlfn.XLOOKUP(Raw_LIMS_Export!E36,'mapping Site table'!$B$4:$B$14,'mapping Site table'!$C$4:$C$14,Raw_LIMS_Export!E36) -> Budapest | E36: Purity_Pct | F36: =IF(I36="",0,1) -> 1 | G36: =IF(I36="", "Missing", IF(AND(I36>=K36, I36<=L36), "Pass", "Fail")) -> Pass | H36: =IF(COUNTIFS($B$2:$B$2016,B36,$G$2:$G$2016,"Fail")>0,"Fail", IF(COUNTIFS($B$2:$B$2016,B36,$G$2:$G$2016,"Missing")>0,"Pending", "Pass")) -> Pass | I36: 98.67 | J36: % | K36: 97 | L36: 100 | M36: =Raw_LIMS_Export!K36 -> 45655 | N36: S. Fischer
A37: S000375 | B37: ARO-2025-00085 | C37: Aroma Chemical | D37: =_xlfn.XLOOKUP(Raw_LIMS_Export!E37,'mapping Site table'!$B$4:$B$14,'mapping Site table'!$C$4:$C$14,Raw_LIMS_Export!E37) -> Dortmund DE | E37: Density_g_ml | F37: =IF(I37="",0,1) -> 1 | G37: =IF(I37="", "Missing", IF(AND(I37>=K37, I37<=L37), "Pass", "Fail")) -> Fail | H37: =IF(COUNTIFS($B$2:$B$2016,B37,$G$2:$G$2016,"Fail")>0,"Fail", IF(COUNTIFS($B$2:$B$2016,B37,$G$2:$G$2016,"Missing")>0,"Pending", "Pass")) -> Fail | I37: 0.79 | J37: g/ml | K37: 0.88 | L37: 0.97 | M37: =Raw_LIMS_Export!K37 -> 45739 | N37: m. toth
A38: S001960 | B38: FRA-2024-00438 | C38: Fragrance Oil | D38: =_xlfn.XLOOKUP(Raw_LIMS_Export!E38,'mapping Site table'!$B$4:$B$14,'mapping Site table'!$C$4:$C$14,Raw_LIMS_Export!E38) -> Budapest | E38: Moisture_Pct | F38: =IF(I38="",0,1) -> 1 | G38: =IF(I38="", "Missing", IF(AND(I38>=K38, I38<=L38), "Pass", "Fail")) -> Pass | H38: =IF(COUNTIFS($B$2:$B$2016,B38,$G$2:$G$2016,"Fail")>0,"Fail", IF(COUNTIFS($B$2:$B$2016,B38,$G$2:$G$2016,"Missing")>0,"Pending", "Pass")) -> Pass | I38: 0.21 | J38: % | K38: 0 | L38: 1 | M38: =Raw_LIMS_Export!K38 -> 45543 | N38: P. Meier
A39: S000673 | B39: FOO-2025-00153 | C39: Food Ingredient Extract | D39: =_xlfn.XLOOKUP(Raw_LIMS_Export!E39,'mapping Site table'!$B$4:$B$14,'mapping Site table'!$C$4:$C$14,Raw_LIMS_Export!E39) -> Dortmund DE | E39: Purity_Pct | F39: =IF(I39="",0,1) -> 1 | G39: =IF(I39="", "Missing", IF(AND(I39>=K39, I39<=L39), "Pass", "Fail")) -> Pass | H39: =IF(COUNTIFS($B$2:$B$2016,B39,$G$2:$G$2016,"Fail")>0,"Fail", IF(COUNTIFS($B$2:$B$2016,B39,$G$2:$G$2016,"Missing")>0,"Pending", "Pass")) -> Fail | I39: 98.78 | J39: % | K39: 97 | L39: 100 | M39: =Raw_LIMS_Export!K39 -> 45845 | N39: A. Kovacs
A40: S001038 | B40: FOO-2024-00233 | C40: Food Ingredient Extract | D40: =_xlfn.XLOOKUP(Raw_LIMS_Export!E40,'mapping Site table'!$B$4:$B$14,'mapping Site table'!$C$4:$C$14,Raw_LIMS_Export!E40) -> Dortmund DE | E40: Microbial_Count_CFU_g | F40: =IF(I40="",0,1) -> 1 | G40: =IF(I40="", "Missing", IF(AND(I40>=K40, I40<=L40), "Pass", "Fail")) -> Fail | H40: =IF(COUNTIFS($B$2:$B$2016,B40,$G$2:$G$2016,"Fail")>0,"Fail", IF(COUNTIFS($B$2:$B$2016,B40,$G$2:$G$2016,"Missing")>0,"Pending", "Pass")) -> Fail | I40: -27.76 | J40: CFU/g | K40: 0 | L40: 100 | M40: =Raw_LIMS_Export!K40 -> 45452 | N40: K. Varga
A41: S000946 | B41: FLA-2024-00214 | C41: Flavor Compound | D41: =_xlfn.XLOOKUP(Raw_LIMS_Export!E41,'mapping Site table'!$B$4:$B$14,'mapping Site table'!$C$4:$C$14,Raw_LIMS_Export!E41) -> East Hanover | E41: Microbial_Count_CFU_g | F41: =IF(I41="",0,1) -> 1 | G41: =IF(I41="", "Missing", IF(AND(I41>=K41, I41<=L41), "Pass", "Fail")) -> Pass | H41: =IF(COUNTIFS($B$2:$B$2016,B41,$G$2:$G$2016,"Fail")>0,"Fail", IF(COUNTIFS($B$2:$B$2016,B41,$G$2:$G$2016,"Missing")>0,"Pending", "Pass")) -> Pass | I41: 30.04 | J41: CFU/g | K41: 0 | L41: 100 | M41: =Raw_LIMS_Export!K41 -> 45398 | N41: M. Toth
...

Sheet Batch_level_table
A1: Batch_ID | B1: Aggregated_Batch_Result | C1: Earliest_Test_Date | D1: Site | E1: Product Line
A2: ARO-2024-00352 | B2: Pending | C2: 45350 | D2: Ashford UK | E2: Aroma Chemical
A3: FOO-2024-00034 | B3: Pass | C3: 45399 | D3: Vernier CH | E3: Food Ingredient Extract
A4: ARO-2025-00025 | B4: Pass | C4: 45924 | D4: East Hanover | E4: Aroma Chemical
A5: ESS-2025-00059 | B5: Pass | C5: 45982 | D5: Vernier CH | E5: Essential Oil Blend
A6: ARO-2024-00311 | B6: Fail | C6: 45488 | D6: East Hanover | E6: Aroma Chemical
A7: FOO-2024-00389 | B7: Pass | C7: 45446 | D7: Ashford UK | E7: Food Ingredient Extract
A8: FOO-2025-00116 | B8: Fail | C8: 46008 | D8: Vernier CH | E8: Food Ingredient Extract
A9: FRA-2024-00338 | B9: Fail | C9: 45501 | D9: Dortmund DE | E9: Fragrance Oil
A10: FLA-2025-00310 | B10: Pass | C10: 45881 | D10: East Hanover | E10: Flavor Compound
A11: FOO-2024-00237 | B11: Pass | C11: 45655 | D11: Budapest | E11: Food Ingredient Extract
A12: ARO-2024-00430 | B12: Fail | C12: 45577 | D12: East Hanover | E12: Aroma Chemical
A13: ARO-2024-00388 | B13: Pending | C13: 45530 | D13: Vernier CH | E13: Aroma Chemical
... A447: ESS-2025-00022 | B447: Pass | C447: 45779 | D447: Budapest | E447: Essential Oil Blend
